# 예외처리(Exception Handling)

## 1.1 프로그램 오류
- 에러(error) : 프로그램 코드에 의해서 수습될 수 **없는** 심각한 오류   
   - 컴파일 에러(compile-time error) : 컴파일 할 때 발생하는 에러    
   - 런타임 에러(runtime error) : 실행 할 때 발생하는 에러   
   - 논리적 에러(logical error) : 작성 의도와 다르게 동작   
    
- 예외(exception) : 프로그램 코드에 의해서 수습될 수 있는 다소 미약한 오류
> 에러(error)는 어쩔 수 없지만, **예외(exception)는 처리하자.**
 
## 1.2 예외처리의 정의와 목적
- 정의 : 프로그램 **실행 시 발생**할 수 있는 예외의 발생에 대비한 코드를 작성하는 것    
- 목적 : 프로그램의 비정상 종료를 막고, 정상적인 실행상태를 유지하는 것   

## 1.3 예외처리 구문 : try-catch
```java
try {
 // 예외가 발생할 가능성이 있는 문장들을 넣는다.
} catch (Exception1 e1) {
 // Exception1이 발생했을 경우, 이를 처리하기 위한 문장을 적는다.
} catch (Exception2 e2) {
 // Exception2가 발생했을 경우, 이를 처리하기 위한 문장을 적는다. 
...
} catch (Exception2N eN) {
 // ExceptionN가 발생했을 경우, 이를 처리하기 위한 문장을 적는다. 
}
```

## 1.4 try-catch문에서의 흐름
#### try블럭 내에서 예외가 발생한 경우    
```
1. 발생한 예외와 일치하는 catch블럭이 있는지 확인한다.     
2. 일치하는 catch블럭을 찾게되면, 그 catch블럭 내의 문장들을 수행하고 전체 try-catch문을 빠져나가서
   그 다음 문장을 계속해서 수행한다. 만약 일치하는 catch블럭을 찾지 못하면, 예외는 처리되지 못한다. 
```
#### try블럭 내에서 예외가 발생하지 않은 경우    
``` 
1. catch블럭을 거치지 않고 전체 try-catch문을 빠져나가서 수행을 계속한다.
```
```java
class ExceptionEx4 {
    public static void main(String[] args) {
        System.out.println(1); // 1
        System.out.println(2); // 2
        
        try {
            System.out.println(3); // 3
            System.out.println(4); // 4
        } catch (Exception e) {
            System.out.println(5); // 예외발생 X -> catch블럭 거치지 않음
        } // try-catch의 끝
        System.out.println(6); // 6
    } // main 메서드의 끝
}
```
```java
class ExceptionEx5 {
    public static void main(String[] args) {
        System.out.println(1); // 1
        System.out.println(2); // 2
        try {
            System.out.println(3); // 3
            System.out.println(0/0); // 예외발생! 
            System.out.println(4);
        } catch (ArithmeticException ae) {
            System.out.println(5); // 5 (발생한 예외와 일치하는 catch블럭 내의 문장 수행)
        } // try-catch의 끝
        System.out.println(6); // 6
    } // main 메서드의 끝
}
```

## 1.5 예외 발생시키기
1. 먼저, 연산자 new를 이용해서 발생시키려는 예외 클래스의 객체를 만든 다음       
`Exception e = new Exception("고의로 발생시켰음");`
2. 키워드 throw를 이용해서 예외를 발생시킨다.    
`throw e;`
```java
class ExceptionEx6 {
    public static void main(String args[]) {
        try {
            Exception e = new Exception("고의로 발생시켰음.");
            throw e; // 예외를 발생시킴
        } catch (Exception e) {
            System.out.println("에러 메시지 : " + e.getMessage();
            e.printStackTrace();
        }
        System.out.println("프로그램이 정상 종료되었습니다.");
    }
}
```

## 1.6 예외 클래스의 계층구조
![](https://t1.daumcdn.net/cfile/tistory/99588B4B5B7261D927)

### `Exception` 과 `RuntimeException`     
- `Exception` 클래스(와 자손클래스)들 : 사용자의 실수와 같은 외적인 요인에 의해 발생하는 예외 => 예외처리 필수       
- `RuntimeException` 클래스(와 자손클래스)들 : 프로그래머의 실수로 발생하는 예외 => 예외처리 선택      

## 1.7 예외의 발생과 catch블럭(1/2)
try블럭에서 예외가 발생하면, 발생한 예외를 처리할 catch블럭을 찾는다.    
첫번쨰 catch블럭부터 순서대로 찾아내려가며, 일치하는 catch블럭이 없으면 예외는 처리되지 않는다.    
예외의 최고 조상인 Exception을 처리하는 catch블럭은 모든 종류의 예외를 처리할 수 있다. **(반드시 마지막 catch블럭이어야 한다.)**

```java
class ExceptionEx11 {
    public static void main(String[] args) {
        System.out.println(1); // 1
        System.out.println(2); // 2
        try {
            System.out.println(3); // 3
            System.out.println(0/0); // ArithmeticException 발생! 
            System.out.println(4); // 실행 안됨
        } catch (ArithmeticException ae) {
            if (ae instanceof ArithmeticException)
                System.out.println("true");
                System.out.println("ArithmeticException");
        } catch (Exception e) {
            System.out.println("Exception");
        } // try-catch의 끝 
        System.out.println(6);
    } // main 메서드의 끝
}
```

